<?xml version="1.0" ?>
<!-- =================================================================================== -->
<!-- |    This document was autogenerated by xacro from robot.urdf.xacro               | -->
<!-- |    EDITING THIS FILE BY HAND IS NOT RECOMMENDED                                 | -->
<!-- =================================================================================== -->
<robot name="limpeza">
  <material name="Cyan">
    <color rgba="0 1.0 1.0 1.0"/>
  </material>
  <!-- Robot -->
  <!-- link: base_footprint -->
  <link name="base_footprint"/>
  <!-- joint: base_footprint -> base -->
  <joint name="joint_base_footprint_to_base" type="fixed">
    <origin rpy="0 0 0" xyz="0 0 0.067"/>
    <parent link="base_footprint"/>
    <child link="base_link"/>
  </joint>
  <!-- link: base -->
  <link name="base_link">
    <visual>
      <origin rpy="0 0 0" xyz="0 0 0"/>
      <geometry>
        <cylinder length="0.2" radius="0.115"/>
      </geometry>
      <material name="Cyan"/>
    </visual>
    <collision>
      <origin rpy="0 0 0" xyz="0 0 0"/>
      <geometry>
        <cylinder length="0.2" radius="0.115"/>
      </geometry>
    </collision>
    <inertial>
      <mass value="2.1"/>
      <inertia ixx="0.013943125" ixy="0.0" ixz="0.0" iyy="0.013943125" iyz="0.0" izz="0.013886250000000001"/>
    </inertial>
  </link>
  <joint name="base_to_laser" type="fixed">
    <origin rpy="0 0 0" xyz="0 0 0.1125"/>
    <parent link="base_link"/>
    <child link="base_scan"/>
  </joint>
  <link name="base_scan">
    <visual>
      <origin rpy="0 0 0" xyz="0 0 0"/>
      <geometry>
        <cylinder length="0.025" radius="0.03833333333333334"/>
      </geometry>
      <material name="Cyan"/>
    </visual>
    <collision>
      <origin rpy="0 0 0" xyz="0 0 0"/>
      <geometry>
        <cylinder length="0.025" radius="0.03833333333333334"/>
      </geometry>
    </collision>
    <inertial>
      <mass value="0.45"/>
      <inertia ixx="0.00018875000000000003" ixy="0.0" ixz="0.0" iyy="0.00018875000000000003" iyz="0.0" izz="0.0003306250000000001"/>
    </inertial>
  </link>
  <!-- joint: parent_base -> wheel -->
  <joint name="base_link_to_left_wheel" type="continuous">
    <origin rpy="0 0 0" xyz="-0.048 -0.048 -0.1335"/>
    <parent link="base_link"/>
    <child link="left_wheel"/>
    <axis xyz="0 0 1"/>
  </joint>
  <!-- link: wheel -->
  <link name="left_wheel">
    <origin rpy="-1.570796325 0 0" xyz="0 0 0"/>
    <visual>
      <origin rpy="0 0 0" xyz="0 0 0"/>
      <geometry>
        <sphere radius="0.0335"/>
      </geometry>
    </visual>
    <collision>
      <origin rpy="0 0 0" xyz="0 0 0"/>
      <geometry>
        <sphere radius="0.0335"/>
      </geometry>
    </collision>
    <inertial>
      <mass value="0.15"/>
      <inertia ixx="6.7335e-05" ixy="0.0" ixz="0.0" iyy="6.7335e-05" iyz="0.0" izz="6.7335e-05"/>
    </inertial>
  </link>
  <!-- joint: parent_base -> wheel -->
  <joint name="base_link_to_right_wheel" type="continuous">
    <origin rpy="0 0 0" xyz="-0.048 0.048 -0.1335"/>
    <parent link="base_link"/>
    <child link="right_wheel"/>
    <axis xyz="0 0 1"/>
  </joint>
  <!-- link: wheel -->
  <link name="right_wheel">
    <origin rpy="-1.570796325 0 0" xyz="0 0 0"/>
    <visual>
      <origin rpy="0 0 0" xyz="0 0 0"/>
      <geometry>
        <sphere radius="0.0335"/>
      </geometry>
    </visual>
    <collision>
      <origin rpy="0 0 0" xyz="0 0 0"/>
      <geometry>
        <sphere radius="0.0335"/>
      </geometry>
    </collision>
    <inertial>
      <mass value="0.15"/>
      <inertia ixx="6.7335e-05" ixy="0.0" ixz="0.0" iyy="6.7335e-05" iyz="0.0" izz="6.7335e-05"/>
    </inertial>
  </link>
  <!-- joint: parent_base -> wheel -->
  <joint name="base_link_to_front_wheel" type="continuous">
    <origin rpy="0 0 0" xyz="0.048 0 -0.0335"/>
    <parent link="base_link"/>
    <child link="front_wheel"/>
    <axis xyz="0 0 1"/>
  </joint>
  <!-- link: wheel -->
  <link name="front_wheel">
    <origin rpy="-1.570796325 0 0" xyz="0 0 0"/>
    <visual>
      <origin rpy="0 0 0" xyz="0 0 0"/>
      <geometry>
        <sphere radius="0.0335"/>
      </geometry>
    </visual>
    <collision>
      <origin rpy="0 0 0" xyz="0 0 0"/>
      <geometry>
        <sphere radius="0.0335"/>
      </geometry>
    </collision>
    <inertial>
      <mass value="0.15"/>
      <inertia ixx="6.7335e-05" ixy="0.0" ixz="0.0" iyy="6.7335e-05" iyz="0.0" izz="6.7335e-05"/>
    </inertial>
  </link>
  <!-- IMU
  <xacro:imu name="imu" parent="base_link">
    <origin xyz="0.0 0.0 0.055" rpy="0 0 0"/>
  </xacro:imu> -->
  <gazebo>
    <plugin filename="libgazebo_ros_diff_drive.so" name="diff_drive">
      <ros>
        <!-- <namespace>/r2d2</namespace> -->
        <!-- <remapping>cmd_vel:=cmd_vel</remapping> -->
        <!-- <remapping>odom:=odom</remapping> -->
      </ros>
      <update_rate>30</update_rate>
      <command_topic>cmd_vel</command_topic>
      <!-- wheels -->
      <left_joint>base_link_to_left_wheel</left_joint>
      <right_joint>base_link_to_right_wheel</right_joint>
      <!-- kinematics -->
      <wheel_separation>0.09</wheel_separation>
      <wheel_diameter>0.067</wheel_diameter>
      <!-- limits -->
      <max_wheel_torque>20</max_wheel_torque>
      <max_wheel_acceleration>1.0</max_wheel_acceleration>
      <!-- output -->
      <publish_odom>true</publish_odom>
      <publish_odom_tf>true</publish_odom_tf>
      <publish_wheel_tf>false</publish_wheel_tf>
      <odometry_topic>odom</odometry_topic>
      <odometry_frame>odom</odometry_frame>
      <robot_base_frame>base_footprint</robot_base_frame>
    </plugin>
  </gazebo>
  <!-- <plugin name="joint_state" filename="libgazebo_ros_joint_state_publisher.so">
      <ros>
        <remapping>~/out:=joint_states</remapping>
      </ros>
      <update_rate>30</update_rate>
      <joint_name>left_leg_base_to_left_center_wheel</joint_name>
      <joint_name>right_leg_base_to_right_center_wheel</joint_name>
      <joint_name>joint_base_footprint_to_base</joint_name>
    </plugin>   -->
  <gazebo reference="base_scan">
    <sensor name="base_scan" type="ray">
      <ray>
        <scan>
          <horizontal>
            <samples>180</samples>
            <resolution>1.0</resolution>
            <min_angle>-1.57</min_angle>
            <max_angle>1.57</max_angle>
          </horizontal>
        </scan>
        <range>
          <min>0.5</min>
          <max>30.0</max>
          <resolution>0.015000</resolution>
        </range>
      </ray>
      <always_on>true</always_on>
      <update_rate>100.0</update_rate>
      <visualize>true</visualize>
      <plugin filename="libgazebo_ros_ray_sensor.so" name="laserscan">
        <ros>
          <remapping>~/out:=scan</remapping>
        </ros>
        <output_type>sensor_msgs/LaserScan</output_type>
        <!-- <frame_name>base_scan</frame_name> -->
      </plugin>
    </sensor>
  </gazebo>
</robot>
