<?xml version="1.0" ?>
<!-- =================================================================================== -->
<!-- |    This document was autogenerated by xacro from robot.urdf.xacro               | -->
<!-- |    EDITING THIS FILE BY HAND IS NOT RECOMMENDED                                 | -->
<!-- =================================================================================== -->
<robot name="garcom">
  <material name="Cyan">
    <color rgba="0 1.0 1.0 1.0"/>
  </material>
  <!-- Robot -->
  <!-- link: base_footprint -->
  <link name="base_footprint"/>
  <!-- joint: base_footprint -> base -->
  <joint name="joint_base_footprint_to_base" type="fixed">
    <origin rpy="0 0 0" xyz="0 0 0.33"/>
    <parent link="base_footprint"/>
    <child link="base_link"/>
  </joint>
  <!-- link: base -->
  <link name="base_link">
    <visual>
      <origin rpy="0 0 0" xyz="0 0 0"/>
      <geometry>
        <cylinder length="0.4" radius="0.2"/>
      </geometry>
      <material name="Cyan"/>
    </visual>
    <collision>
      <origin rpy="0 0 0" xyz="0 0 0"/>
      <geometry>
        <cylinder length="0.4" radius="0.2"/>
      </geometry>
    </collision>
    <inertial>
      <mass value="2.0"/>
      <inertia ixx="0.04666666666666667" ixy="0.0" ixz="0.0" iyy="0.04666666666666667" iyz="0.0" izz="0.04000000000000001"/>
    </inertial>
  </link>
  <joint name="base_to_laser" type="fixed">
    <origin rpy="0 0 0" xyz="0 0 0.2125"/>
    <parent link="base_link"/>
    <child link="base_scan"/>
  </joint>
  <link name="base_scan">
    <visual>
      <origin rpy="0 0 0" xyz="0 0 0"/>
      <geometry>
        <cylinder length="0.025" radius="0.2"/>
      </geometry>
      <material name="Cyan"/>
    </visual>
    <collision>
      <origin rpy="0 0 0" xyz="0 0 0"/>
      <geometry>
        <cylinder length="0.025" radius="0.2"/>
      </geometry>
    </collision>
    <inertial>
      <mass value="1.0"/>
      <inertia ixx="0.010052083333333335" ixy="0.0" ixz="0.0" iyy="0.010052083333333335" iyz="0.0" izz="0.020000000000000004"/>
    </inertial>
  </link>
  <!-- link: base -->
  <link name="plate_bottom">
    <visual>
      <origin rpy="0 0 0" xyz="0 0 0"/>
      <geometry>
        <cylinder length="0.02" radius="0.2"/>
      </geometry>
      <material name="Cyan"/>
    </visual>
    <collision>
      <origin rpy="0 0 0" xyz="0 0 0"/>
      <geometry>
        <cylinder length="0.02" radius="0.2"/>
      </geometry>
    </collision>
    <inertial>
      <mass value="0.5"/>
      <inertia ixx="0.0050166666666666675" ixy="0.0" ixz="0.0" iyy="0.0050166666666666675" iyz="0.0" izz="0.010000000000000002"/>
    </inertial>
  </link>
  <!-- joint: torso -> laser -->
  <joint name="torso_to_laser" type="fixed">
    <origin rpy="0 0 0" xyz="0 0 0.2125"/>
    <parent link="base_scan"/>
    <child link="torso"/>
  </joint>
  <!-- link: base -->
  <link name="torso">
    <visual>
      <origin rpy="0 0 0" xyz="0 0 0"/>
      <geometry>
        <cylinder length="0.4" radius="0.2"/>
      </geometry>
      <material name="Cyan"/>
    </visual>
    <collision>
      <origin rpy="0 0 0" xyz="0 0 0"/>
      <geometry>
        <cylinder length="0.4" radius="0.2"/>
      </geometry>
    </collision>
    <inertial>
      <mass value="2.0"/>
      <inertia ixx="0.04666666666666667" ixy="0.0" ixz="0.0" iyy="0.04666666666666667" iyz="0.0" izz="0.04000000000000001"/>
    </inertial>
  </link>
  <!-- joint: torso -> laser -->
  <joint name="torso_to_plate" type="fixed">
    <origin rpy="0 0 0" xyz="0 0 0.21"/>
    <parent link="torso"/>
    <child link="plate_bottom"/>
  </joint>
  <!-- link: base -->
  <link name="plate_middle">
    <visual>
      <origin rpy="0 0 0" xyz="0 0 0"/>
      <geometry>
        <cylinder length="0.02" radius="0.2"/>
      </geometry>
      <material name="Cyan"/>
    </visual>
    <collision>
      <origin rpy="0 0 0" xyz="0 0 0"/>
      <geometry>
        <cylinder length="0.02" radius="0.2"/>
      </geometry>
    </collision>
    <inertial>
      <mass value="0.5"/>
      <inertia ixx="0.0050166666666666675" ixy="0.0" ixz="0.0" iyy="0.0050166666666666675" iyz="0.0" izz="0.010000000000000002"/>
    </inertial>
  </link>
  <!-- link: base -->
  <link name="plate_top">
    <visual>
      <origin rpy="0 0 0" xyz="0 0 0"/>
      <geometry>
        <cylinder length="0.02" radius="0.2"/>
      </geometry>
      <material name="Cyan"/>
    </visual>
    <collision>
      <origin rpy="0 0 0" xyz="0 0 0"/>
      <geometry>
        <cylinder length="0.02" radius="0.2"/>
      </geometry>
    </collision>
    <inertial>
      <mass value="0.5"/>
      <inertia ixx="0.0050166666666666675" ixy="0.0" ixz="0.0" iyy="0.0050166666666666675" iyz="0.0" izz="0.010000000000000002"/>
    </inertial>
  </link>
  <!-- joint: plate -> holder -->
  <joint name="plate_bottom_to_holder1" type="fixed">
    <origin rpy="0 0 0" xyz="0 0 0.11"/>
    <parent link="plate_bottom"/>
    <child link="holder1"/>
  </joint>
  <joint name="holder1_to_plate_middle" type="fixed">
    <origin rpy="0 0 0" xyz="0 0 0.11"/>
    <parent link="holder1"/>
    <child link="plate_middle"/>
  </joint>
  <!-- link: base -->
  <link name="holder1">
    <visual>
      <origin rpy="0 0 0" xyz="0.12 0.12 0"/>
      <geometry>
        <cylinder length="0.2" radius="0.02"/>
      </geometry>
      <material name="Cyan"/>
    </visual>
    <collision>
      <origin rpy="0 0 0" xyz="0.12 0.12 0"/>
      <geometry>
        <cylinder length="0.2" radius="0.02"/>
      </geometry>
    </collision>
    <inertial>
      <mass value="0.125"/>
      <inertia ixx="0.0004291666666666667" ixy="0.0" ixz="0.0" iyy="0.0004291666666666667" iyz="0.0" izz="2.5e-05"/>
    </inertial>
    <visual>
      <origin rpy="0 0 0" xyz="-0.12 -0.12 0"/>
      <geometry>
        <cylinder length="0.2" radius="0.02"/>
      </geometry>
      <material name="Cyan"/>
    </visual>
    <collision>
      <origin rpy="0 0 0" xyz="-0.12 -0.12 0"/>
      <geometry>
        <cylinder length="0.2" radius="0.02"/>
      </geometry>
    </collision>
    <inertial>
      <mass value="0.125"/>
      <inertia ixx="0.0004291666666666667" ixy="0.0" ixz="0.0" iyy="0.0004291666666666667" iyz="0.0" izz="2.5e-05"/>
    </inertial>
    <visual>
      <origin rpy="0 0 0" xyz="0.12 -0.12 0"/>
      <geometry>
        <cylinder length="0.2" radius="0.02"/>
      </geometry>
      <material name="Cyan"/>
    </visual>
    <collision>
      <origin rpy="0 0 0" xyz="0.12 -0.12 0"/>
      <geometry>
        <cylinder length="0.2" radius="0.02"/>
      </geometry>
    </collision>
    <inertial>
      <mass value="0.125"/>
      <inertia ixx="0.0004291666666666667" ixy="0.0" ixz="0.0" iyy="0.0004291666666666667" iyz="0.0" izz="2.5e-05"/>
    </inertial>
    <visual>
      <origin rpy="0 0 0" xyz="-0.12 0.12 0"/>
      <geometry>
        <cylinder length="0.2" radius="0.02"/>
      </geometry>
      <material name="Cyan"/>
    </visual>
    <collision>
      <origin rpy="0 0 0" xyz="-0.12 0.12 0"/>
      <geometry>
        <cylinder length="0.2" radius="0.02"/>
      </geometry>
    </collision>
    <inertial>
      <mass value="0.125"/>
      <inertia ixx="0.0004291666666666667" ixy="0.0" ixz="0.0" iyy="0.0004291666666666667" iyz="0.0" izz="2.5e-05"/>
    </inertial>
  </link>
  <!-- joint: plate -> holder -->
  <joint name="plate_middle_to_holder2" type="fixed">
    <origin rpy="0 0 0" xyz="0 0 0.11"/>
    <parent link="plate_middle"/>
    <child link="holder2"/>
  </joint>
  <joint name="holder2_to_plate_top" type="fixed">
    <origin rpy="0 0 0" xyz="0 0 0.11"/>
    <parent link="holder2"/>
    <child link="plate_top"/>
  </joint>
  <!-- link: base -->
  <link name="holder2">
    <visual>
      <origin rpy="0 0 0" xyz="0.12 0.12 0"/>
      <geometry>
        <cylinder length="0.2" radius="0.02"/>
      </geometry>
      <material name="Cyan"/>
    </visual>
    <collision>
      <origin rpy="0 0 0" xyz="0.12 0.12 0"/>
      <geometry>
        <cylinder length="0.2" radius="0.02"/>
      </geometry>
    </collision>
    <inertial>
      <mass value="0.125"/>
      <inertia ixx="0.0004291666666666667" ixy="0.0" ixz="0.0" iyy="0.0004291666666666667" iyz="0.0" izz="2.5e-05"/>
    </inertial>
    <visual>
      <origin rpy="0 0 0" xyz="-0.12 -0.12 0"/>
      <geometry>
        <cylinder length="0.2" radius="0.02"/>
      </geometry>
      <material name="Cyan"/>
    </visual>
    <collision>
      <origin rpy="0 0 0" xyz="-0.12 -0.12 0"/>
      <geometry>
        <cylinder length="0.2" radius="0.02"/>
      </geometry>
    </collision>
    <inertial>
      <mass value="0.125"/>
      <inertia ixx="0.0004291666666666667" ixy="0.0" ixz="0.0" iyy="0.0004291666666666667" iyz="0.0" izz="2.5e-05"/>
    </inertial>
    <visual>
      <origin rpy="0 0 0" xyz="0.12 -0.12 0"/>
      <geometry>
        <cylinder length="0.2" radius="0.02"/>
      </geometry>
      <material name="Cyan"/>
    </visual>
    <collision>
      <origin rpy="0 0 0" xyz="0.12 -0.12 0"/>
      <geometry>
        <cylinder length="0.2" radius="0.02"/>
      </geometry>
    </collision>
    <inertial>
      <mass value="0.125"/>
      <inertia ixx="0.0004291666666666667" ixy="0.0" ixz="0.0" iyy="0.0004291666666666667" iyz="0.0" izz="2.5e-05"/>
    </inertial>
    <visual>
      <origin rpy="0 0 0" xyz="-0.12 0.12 0"/>
      <geometry>
        <cylinder length="0.2" radius="0.02"/>
      </geometry>
      <material name="Cyan"/>
    </visual>
    <collision>
      <origin rpy="0 0 0" xyz="-0.12 0.12 0"/>
      <geometry>
        <cylinder length="0.2" radius="0.02"/>
      </geometry>
    </collision>
    <inertial>
      <mass value="0.125"/>
      <inertia ixx="0.0004291666666666667" ixy="0.0" ixz="0.0" iyy="0.0004291666666666667" iyz="0.0" izz="2.5e-05"/>
    </inertial>
  </link>
  <!-- joint: screen -> plate -->
  <joint name="plate_top_to_screen_front" type="fixed">
    <origin rpy="0 0 0" xyz="0.18 0 0.02"/>
    <parent link="plate_top"/>
    <child link="screen_front"/>
  </joint>
  <!-- link: base -->
  <link name="screen_front">
    <visual>
      <origin rpy="0 0 0" xyz="0 0 0"/>
      <geometry>
        <box size="0.05 0.2 0.2"/>
      </geometry>
      <material name="Cyan"/>
    </visual>
    <collision>
      <origin rpy="0 0 0" xyz="0 0 0"/>
      <geometry>
        <box size="0.05 0.2 0.2"/>
      </geometry>
    </collision>
    <inertial>
      <mass value="0.4"/>
      <inertia ixx="0.002666666666666667" ixy="0.0" ixz="0.0" iyy="0.001416666666666667" iyz="0.0" izz="0.001416666666666667"/>
    </inertial>
  </link>
  <!-- joint: screen -> plate -->
  <joint name="plate_top_to_screen_back" type="fixed">
    <origin rpy="0 0 0" xyz="-0.18 0 0.02"/>
    <parent link="plate_top"/>
    <child link="screen_back"/>
  </joint>
  <!-- link: base -->
  <link name="screen_back">
    <visual>
      <origin rpy="0 0 0" xyz="0 0 0"/>
      <geometry>
        <box size="0.05 0.2 0.2"/>
      </geometry>
      <material name="Cyan"/>
    </visual>
    <collision>
      <origin rpy="0 0 0" xyz="0 0 0"/>
      <geometry>
        <box size="0.05 0.2 0.2"/>
      </geometry>
    </collision>
    <inertial>
      <mass value="0.4"/>
      <inertia ixx="0.002666666666666667" ixy="0.0" ixz="0.0" iyy="0.001416666666666667" iyz="0.0" izz="0.001416666666666667"/>
    </inertial>
  </link>
  <!-- joint: camera -> screen -->
  <joint name="screen_front_to_camera_frente" type="fixed">
    <origin rpy="0 0 0" xyz="0 0 0.11"/>
    <parent link="screen_front"/>
    <child link="camera_frente"/>
  </joint>
  <!-- link: base -->
  <link name="camera_frente">
    <visual>
      <origin rpy="0 0 0" xyz="0 0 0"/>
      <geometry>
        <box size="0.025 0.025 0.02"/>
      </geometry>
      <material name="Cyan"/>
    </visual>
    <collision>
      <origin rpy="0 0 0" xyz="0 0 0"/>
      <geometry>
        <box size="0.025 0.025 0.02"/>
      </geometry>
    </collision>
    <inertial>
      <mass value="0.2"/>
      <inertia ixx="1.7083333333333333e-05" ixy="0.0" ixz="0.0" iyy="1.7083333333333333e-05" iyz="0.0" izz="2.0833333333333336e-05"/>
    </inertial>
  </link>
  <!-- joint: parent_base -> wheel -->
  <joint name="base_link_to_left_wheel" type="continuous">
    <origin rpy="0 0 0" xyz="-0.09 -0.09 -0.25"/>
    <parent link="base_link"/>
    <child link="left_wheel"/>
    <axis xyz="0 0 1"/>
  </joint>
  <!-- link: wheel -->
  <link name="left_wheel">
    <origin rpy="-1.570796325 0 0" xyz="0 0 0"/>
    <visual>
      <origin rpy="0 0 0" xyz="0 0 0"/>
      <geometry>
        <sphere radius="0.06666666666666667"/>
      </geometry>
    </visual>
    <collision>
      <origin rpy="0 0 0" xyz="0 0 0"/>
      <geometry>
        <sphere radius="0.06666666666666667"/>
      </geometry>
    </collision>
    <inertial>
      <mass value="0.5"/>
      <inertia ixx="0.0008888888888888889" ixy="0.0" ixz="0.0" iyy="0.0008888888888888889" iyz="0.0" izz="0.0008888888888888889"/>
    </inertial>
  </link>
  <!-- joint: parent_base -> wheel -->
  <joint name="base_link_to_right_wheel" type="continuous">
    <origin rpy="0 0 0" xyz="-0.09 0.09 -0.25"/>
    <parent link="base_link"/>
    <child link="right_wheel"/>
    <axis xyz="0 0 1"/>
  </joint>
  <!-- link: wheel -->
  <link name="right_wheel">
    <origin rpy="-1.570796325 0 0" xyz="0 0 0"/>
    <visual>
      <origin rpy="0 0 0" xyz="0 0 0"/>
      <geometry>
        <sphere radius="0.06666666666666667"/>
      </geometry>
    </visual>
    <collision>
      <origin rpy="0 0 0" xyz="0 0 0"/>
      <geometry>
        <sphere radius="0.06666666666666667"/>
      </geometry>
    </collision>
    <inertial>
      <mass value="0.5"/>
      <inertia ixx="0.0008888888888888889" ixy="0.0" ixz="0.0" iyy="0.0008888888888888889" iyz="0.0" izz="0.0008888888888888889"/>
    </inertial>
  </link>
  <!-- joint: parent_base -> wheel -->
  <joint name="base_link_to_front_wheel" type="continuous">
    <origin rpy="0 0 0" xyz="0.09 0 -0.25"/>
    <parent link="base_link"/>
    <child link="front_wheel"/>
    <axis xyz="0 0 1"/>
  </joint>
  <!-- link: wheel -->
  <link name="front_wheel">
    <origin rpy="-1.570796325 0 0" xyz="0 0 0"/>
    <visual>
      <origin rpy="0 0 0" xyz="0 0 0"/>
      <geometry>
        <sphere radius="0.06666666666666667"/>
      </geometry>
    </visual>
    <collision>
      <origin rpy="0 0 0" xyz="0 0 0"/>
      <geometry>
        <sphere radius="0.06666666666666667"/>
      </geometry>
    </collision>
    <inertial>
      <mass value="0.5"/>
      <inertia ixx="0.0008888888888888889" ixy="0.0" ixz="0.0" iyy="0.0008888888888888889" iyz="0.0" izz="0.0008888888888888889"/>
    </inertial>
  </link>
  <joint name="base_link_to_imu" type="fixed">
    <origin rpy="0 0 0" xyz="0.0 0.0 0.055"/>
    <parent link="base_link"/>
    <child link="imu"/>
  </joint>
  <link name="imu">
    <visual>
      <geometry>
        <box size="0.2 0.2 0.05"/>
      </geometry>
    </visual>
    <collision>
      <geometry>
        <box size="0.2 0.2 0.05"/>
      </geometry>
    </collision>
    <inertial>
      <mass value="1e-5"/>
      <origin rpy="0 0 0" xyz="0 0 0"/>
      <inertia ixx="1e-6" ixy="0" ixz="0" iyy="1e-6" iyz="0" izz="1e-6"/>
    </inertial>
  </link>
  <gazebo reference="imu">
    <gravity>true</gravity>
    <sensor name="imu_sensor" type="imu">
      <always_on>true</always_on>
      <update_rate>100</update_rate>
      <visualize>true</visualize>
      <pose>0 0 0 0 0 0</pose>
      <plugin filename="libgazebo_ros_imu_sensor.so" name="imu_plugin">
        <ros>
          <!-- publish to /imu/data -->
          <!-- <namespace>/bno055</namespace> -->
          <remapping>~/out:=imu</remapping>
        </ros>
        <topicName>imu</topicName>
        <bodyName>imu</bodyName>
        <updateRateHZ>50.0</updateRateHZ>
        <gaussianNoise>0.005</gaussianNoise>
        <xyzOffset>0 0 0</xyzOffset>
        <rpyOffset>0 0 0</rpyOffset>
        <frameName>imu</frameName>
      </plugin>
    </sensor>
  </gazebo>
  <!-- 
  <gazebo reference="imu_link">
    <sensor name="imu_sensor" type="imu">
      <plugin filename="libgazebo_ros_imu_sensor.so" name="imu_plugin">
        <ros>
          <namespace>/bno055</namespace>
          <remapping>~/out:=imu</remapping>
        </ros>
        <initial_orientation_as_reference>false</initial_orientation_as_reference>
      </plugin>
      <always_on>true</always_on>
      <update_rate>100</update_rate>
      <visualize>true</visualize>
     <imu>
     	<angular_velocity>
     	  <x>
     	    <noise type="gaussian">
              <mean>0.0</mean>
              <stddev>2e-4</stddev>
              <bias_mean>0.0000075</bias_mean>
              <bias_stddev>0.0000008</bias_stddev>
            </noise>
          </x>
          <y>
            <noise type="gaussian">
              <mean>0.0</mean>
              <stddev>2e-4</stddev>
              <bias_mean>0.0000075</bias_mean>
              <bias_stddev>0.0000008</bias_stddev>
            </noise>
          </y>
          <z>
            <noise type="gaussian">
              <mean>0.0</mean>
              <stddev>2e-4</stddev>
              <bias_mean>0.0000075</bias_mean>
              <bias_stddev>0.0000008</bias_stddev>
            </noise>
          </z>
        </angular_velocity>
        <linear_acceleration>
          <x>
            <noise type="gaussian">
              <mean>0.0</mean>
              <stddev>1.7e-2</stddev>
              <bias_mean>0.1</bias_mean>
              <bias_stddev>0.001</bias_stddev>
            </noise>
          </x>
          <y>
            <noise type="gaussian">
              <mean>0.0</mean>
              <stddev>1.7e-2</stddev>
              <bias_mean>0.1</bias_mean>
              <bias_stddev>0.001</bias_stddev>
            </noise>
          </y>
          <z>
            <noise type="gaussian">
              <mean>0.0</mean>
              <stddev>1.7e-2</stddev>
              <bias_mean>0.1</bias_mean>
              <bias_stddev>0.001</bias_stddev>
            </noise>
          </z>
        </linear_acceleration>
      </imu>
    </sensor>
  </gazebo>
   -->
  <gazebo>
    <plugin filename="libgazebo_ros_diff_drive.so" name="diff_drive">
      <ros>
        <!-- <namespace>/r2d2</namespace> -->
        <!-- <remapping>cmd_vel:=cmd_vel</remapping> -->
        <!-- <remapping>odom:=odom</remapping> -->
      </ros>
      <update_rate>30</update_rate>
      <command_topic>cmd_vel</command_topic>
      <!-- wheels -->
      <left_joint>base_link_to_left_wheel</left_joint>
      <right_joint>base_link_to_right_wheel</right_joint>
      <!-- kinematics -->
      <wheel_separation>0.025</wheel_separation>
      <wheel_diameter>0.13</wheel_diameter>
      <!-- limits -->
      <max_wheel_torque>20</max_wheel_torque>
      <max_wheel_acceleration>1.0</max_wheel_acceleration>
      <!-- output -->
      <publish_odom>true</publish_odom>
      <publish_odom_tf>true</publish_odom_tf>
      <publish_wheel_tf>false</publish_wheel_tf>
      <odometry_topic>odom</odometry_topic>
      <odometry_frame>odom</odometry_frame>
      <robot_base_frame>base_footprint</robot_base_frame>
    </plugin>
  </gazebo>
  <!-- <plugin name="joint_state" filename="libgazebo_ros_joint_state_publisher.so">
      <ros>
        <remapping>~/out:=joint_states</remapping>
      </ros>
      <update_rate>30</update_rate>
      <joint_name>left_leg_base_to_left_center_wheel</joint_name>
      <joint_name>right_leg_base_to_right_center_wheel</joint_name>
      <joint_name>joint_base_footprint_to_base</joint_name>
    </plugin>   -->
  <gazebo reference="base_scan">
    <sensor name="base_scan" type="ray">
      <ray>
        <scan>
          <horizontal>
            <samples>180</samples>
            <resolution>1.0</resolution>
            <min_angle>-1.57</min_angle>
            <max_angle>1.57</max_angle>
          </horizontal>
        </scan>
        <range>
          <min>0.5</min>
          <max>30.0</max>
          <resolution>0.015000</resolution>
        </range>
      </ray>
      <always_on>true</always_on>
      <update_rate>100.0</update_rate>
      <visualize>true</visualize>
      <plugin filename="libgazebo_ros_ray_sensor.so" name="laserscan">
        <ros>
          <remapping>~/out:=scan</remapping>
        </ros>
        <output_type>sensor_msgs/LaserScan</output_type>
        <!-- <frame_name>base_scan</frame_name> -->
      </plugin>
    </sensor>
  </gazebo>
  <gazebo reference="camera_frente">
    <!-- <sensor name="sensor_${reference}" type="camera">

        <camera>
          <horizontal_fov>1.3962634</horizontal_fov>
          <image>
            <width>800</width>
            <height>800</height>
            <format>R8G8B8</format>
          </image>
          <clip>
            <near>0.04</near>
            <far>300</far>
          </clip>
        </camera>

        <plugin name="${reference}_controller" filename="libgazebo_ros_camera.so">
          <alwaysOn>true</alwaysOn>
          <updateRate>0.0</updateRate>
          <cameraName>camera_${reference}</cameraName>
          <imageTopicName>image_raw</imageTopicName>
          <cameraInfoTopicName>camera_info</cameraInfoTopicName>
          <frameName>${reference}</frameName>
          <hackBaseline>0.07</hackBaseline>
          <distortionK1>0.0</distortionK1>
          <distortionK2>0.0</distortionK2>
          <distortionK3>0.0</distortionK3>
          <distortionT1>0.0</distortionT1>
          <distortionT2>0.0</distortionT2>
        </plugin>

      </sensor> -->
    <sensor name="camera1" type="camera">
      <update_rate>60</update_rate>
      <visualize>true</visualize>
      <camera name="camera_frente">
        <horizontal_fov>1.3962634</horizontal_fov>
        <image>
          <width>640</width>
          <height>480</height>
          <format>R8G8B8</format>
        </image>
        <clip>
          <near>0.02</near>
          <far>300</far>
        </clip>
        <noise>
          <type>gaussian</type>
          <mean>0.0</mean>
          <stddev>0.007</stddev>
        </noise>
      </camera>
      <plugin filename="libgazebo_ros_camera.so" name="camera_controller">
        <ros>
          <namespace>r2d2</namespace>
          <!-- TODO(louise) Remapping not working due to https://github.com/ros-perception/image_common/issues/93 -->
          <!-- <remapping>image_raw:=image_demo</remapping> -->
          <!-- <remapping>camera_info:=camera_info_demo</remapping> -->
        </ros>
        <!-- camera_name>omit so it defaults to sensor name</camera_name-->
        <!-- frame_name>omit so it defaults to link name</frame_name-->
      </plugin>
    </sensor>
  </gazebo>
</robot>
