<?xml version="1.0" ?>
<!-- =================================================================================== -->
<!-- |    This document was autogenerated by xacro from robot.urdf.xacro               | -->
<!-- |    EDITING THIS FILE BY HAND IS NOT RECOMMENDED                                 | -->
<!-- =================================================================================== -->
<robot name="garcom">
  <material name="Cyan">
    <color rgba="0 1.0 1.0 1.0"/>
  </material>
  <!-- Robot -->
  <!-- link: base_footprint -->
  <link name="base_footprint"/>
  <!-- joint: base_footprint -> base -->
  <joint name="joint_base_footprint_to_base" type="fixed">
    <origin rpy="0 0 0" xyz="0 0 0.175"/>
    <parent link="base_footprint"/>
    <child link="base_scan"/>
  </joint>
  <!-- link: base -->
  <link name="base_link">
    <visual>
      <origin rpy="0 0 0" xyz="0 0 0"/>
      <geometry>
        <cylinder length="0.4" radius="0.3"/>
      </geometry>
      <material name="Cyan"/>
    </visual>
    <collision>
      <origin rpy="0 0 0" xyz="0 0 0"/>
      <geometry>
        <cylinder length="0.4" radius="0.3"/>
      </geometry>
    </collision>
    <inertial>
      <mass value="1.0"/>
      <inertia ixx="0.03583333333333333" ixy="0.0" ixz="0.0" iyy="0.03583333333333333" iyz="0.0" izz="0.045"/>
    </inertial>
  </link>
  <joint name="base_to_laser" type="fixed">
    <origin rpy="0 0 0" xyz="0 0 0.2125"/>
    <parent link="base_scan"/>
    <child link="base_link"/>
  </joint>
  <link name="base_scan">
    <visual>
      <origin rpy="0 0 0" xyz="0 0 0"/>
      <geometry>
        <cylinder length="0.025" radius="0.3"/>
      </geometry>
      <material name="Cyan"/>
    </visual>
    <collision>
      <origin rpy="0 0 0" xyz="0 0 0"/>
      <geometry>
        <cylinder length="0.025" radius="0.3"/>
      </geometry>
    </collision>
    <inertial>
      <mass value="5.0"/>
      <inertia ixx="0.11276041666666664" ixy="0.0" ixz="0.0" iyy="0.11276041666666664" iyz="0.0" izz="0.22499999999999998"/>
    </inertial>
  </link>
  <joint name="base_to_plate" type="fixed">
    <origin rpy="0 0 0" xyz="0 0 0.21"/>
    <parent link="base_link"/>
    <child link="plate_bottom"/>
  </joint>
  <!-- link: base -->
  <link name="plate_bottom">
    <visual>
      <origin rpy="0 0 0" xyz="0 0 0"/>
      <geometry>
        <cylinder length="0.02" radius="0.3"/>
      </geometry>
      <material name="Cyan"/>
    </visual>
    <collision>
      <origin rpy="0 0 0" xyz="0 0 0"/>
      <geometry>
        <cylinder length="0.02" radius="0.3"/>
      </geometry>
    </collision>
    <inertial>
      <mass value="0.4"/>
      <inertia ixx="0.009013333333333332" ixy="0.0" ixz="0.0" iyy="0.009013333333333332" iyz="0.0" izz="0.018"/>
    </inertial>
  </link>
  <!-- link: base -->
  <link name="plate_middle">
    <visual>
      <origin rpy="0 0 0" xyz="0 0 0"/>
      <geometry>
        <cylinder length="0.02" radius="0.3"/>
      </geometry>
      <material name="Cyan"/>
    </visual>
    <collision>
      <origin rpy="0 0 0" xyz="0 0 0"/>
      <geometry>
        <cylinder length="0.02" radius="0.3"/>
      </geometry>
    </collision>
    <inertial>
      <mass value="0.4"/>
      <inertia ixx="0.009013333333333332" ixy="0.0" ixz="0.0" iyy="0.009013333333333332" iyz="0.0" izz="0.018"/>
    </inertial>
  </link>
  <!-- link: base -->
  <link name="plate_top">
    <visual>
      <origin rpy="0 0 0" xyz="0 0 0"/>
      <geometry>
        <cylinder length="0.02" radius="0.3"/>
      </geometry>
      <material name="Cyan"/>
    </visual>
    <collision>
      <origin rpy="0 0 0" xyz="0 0 0"/>
      <geometry>
        <cylinder length="0.02" radius="0.3"/>
      </geometry>
    </collision>
    <inertial>
      <mass value="0.4"/>
      <inertia ixx="0.009013333333333332" ixy="0.0" ixz="0.0" iyy="0.009013333333333332" iyz="0.0" izz="0.018"/>
    </inertial>
  </link>
  <!-- joint: plate -> holder -->
  <joint name="plate_bottom_to_holder1" type="fixed">
    <origin rpy="0 0 0" xyz="0 0 0.11"/>
    <parent link="plate_bottom"/>
    <child link="holder1"/>
  </joint>
  <joint name="holder1_to_plate_middle" type="fixed">
    <origin rpy="0 0 0" xyz="0 0 0.11"/>
    <parent link="holder1"/>
    <child link="plate_middle"/>
  </joint>
  <!-- link: base -->
  <link name="holder1">
    <visual>
      <origin rpy="0 0 0" xyz="0.12 0.12 0"/>
      <geometry>
        <cylinder length="0.2" radius="0.02"/>
      </geometry>
      <material name="Cyan"/>
    </visual>
    <collision>
      <origin rpy="0 0 0" xyz="0.12 0.12 0"/>
      <geometry>
        <cylinder length="0.2" radius="0.02"/>
      </geometry>
    </collision>
    <inertial>
      <mass value="0.5"/>
      <inertia ixx="0.001716666666666667" ixy="0.0" ixz="0.0" iyy="0.001716666666666667" iyz="0.0" izz="0.0001"/>
    </inertial>
    <visual>
      <origin rpy="0 0 0" xyz="-0.12 -0.12 0"/>
      <geometry>
        <cylinder length="0.2" radius="0.02"/>
      </geometry>
      <material name="Cyan"/>
    </visual>
    <collision>
      <origin rpy="0 0 0" xyz="-0.12 -0.12 0"/>
      <geometry>
        <cylinder length="0.2" radius="0.02"/>
      </geometry>
    </collision>
    <inertial>
      <mass value="0.5"/>
      <inertia ixx="0.001716666666666667" ixy="0.0" ixz="0.0" iyy="0.001716666666666667" iyz="0.0" izz="0.0001"/>
    </inertial>
    <visual>
      <origin rpy="0 0 0" xyz="0.12 -0.12 0"/>
      <geometry>
        <cylinder length="0.2" radius="0.02"/>
      </geometry>
      <material name="Cyan"/>
    </visual>
    <collision>
      <origin rpy="0 0 0" xyz="0.12 -0.12 0"/>
      <geometry>
        <cylinder length="0.2" radius="0.02"/>
      </geometry>
    </collision>
    <inertial>
      <mass value="0.5"/>
      <inertia ixx="0.001716666666666667" ixy="0.0" ixz="0.0" iyy="0.001716666666666667" iyz="0.0" izz="0.0001"/>
    </inertial>
    <visual>
      <origin rpy="0 0 0" xyz="-0.12 0.12 0"/>
      <geometry>
        <cylinder length="0.2" radius="0.02"/>
      </geometry>
      <material name="Cyan"/>
    </visual>
    <collision>
      <origin rpy="0 0 0" xyz="-0.12 0.12 0"/>
      <geometry>
        <cylinder length="0.2" radius="0.02"/>
      </geometry>
    </collision>
    <inertial>
      <mass value="0.5"/>
      <inertia ixx="0.001716666666666667" ixy="0.0" ixz="0.0" iyy="0.001716666666666667" iyz="0.0" izz="0.0001"/>
    </inertial>
  </link>
  <!-- joint: plate -> holder -->
  <joint name="plate_middle_to_holder2" type="fixed">
    <origin rpy="0 0 0" xyz="0 0 0.11"/>
    <parent link="plate_middle"/>
    <child link="holder2"/>
  </joint>
  <joint name="holder2_to_plate_top" type="fixed">
    <origin rpy="0 0 0" xyz="0 0 0.11"/>
    <parent link="holder2"/>
    <child link="plate_top"/>
  </joint>
  <!-- link: base -->
  <link name="holder2">
    <visual>
      <origin rpy="0 0 0" xyz="0.12 0.12 0"/>
      <geometry>
        <cylinder length="0.2" radius="0.02"/>
      </geometry>
      <material name="Cyan"/>
    </visual>
    <collision>
      <origin rpy="0 0 0" xyz="0.12 0.12 0"/>
      <geometry>
        <cylinder length="0.2" radius="0.02"/>
      </geometry>
    </collision>
    <inertial>
      <mass value="0.5"/>
      <inertia ixx="0.001716666666666667" ixy="0.0" ixz="0.0" iyy="0.001716666666666667" iyz="0.0" izz="0.0001"/>
    </inertial>
    <visual>
      <origin rpy="0 0 0" xyz="-0.12 -0.12 0"/>
      <geometry>
        <cylinder length="0.2" radius="0.02"/>
      </geometry>
      <material name="Cyan"/>
    </visual>
    <collision>
      <origin rpy="0 0 0" xyz="-0.12 -0.12 0"/>
      <geometry>
        <cylinder length="0.2" radius="0.02"/>
      </geometry>
    </collision>
    <inertial>
      <mass value="0.5"/>
      <inertia ixx="0.001716666666666667" ixy="0.0" ixz="0.0" iyy="0.001716666666666667" iyz="0.0" izz="0.0001"/>
    </inertial>
    <visual>
      <origin rpy="0 0 0" xyz="0.12 -0.12 0"/>
      <geometry>
        <cylinder length="0.2" radius="0.02"/>
      </geometry>
      <material name="Cyan"/>
    </visual>
    <collision>
      <origin rpy="0 0 0" xyz="0.12 -0.12 0"/>
      <geometry>
        <cylinder length="0.2" radius="0.02"/>
      </geometry>
    </collision>
    <inertial>
      <mass value="0.5"/>
      <inertia ixx="0.001716666666666667" ixy="0.0" ixz="0.0" iyy="0.001716666666666667" iyz="0.0" izz="0.0001"/>
    </inertial>
    <visual>
      <origin rpy="0 0 0" xyz="-0.12 0.12 0"/>
      <geometry>
        <cylinder length="0.2" radius="0.02"/>
      </geometry>
      <material name="Cyan"/>
    </visual>
    <collision>
      <origin rpy="0 0 0" xyz="-0.12 0.12 0"/>
      <geometry>
        <cylinder length="0.2" radius="0.02"/>
      </geometry>
    </collision>
    <inertial>
      <mass value="0.5"/>
      <inertia ixx="0.001716666666666667" ixy="0.0" ixz="0.0" iyy="0.001716666666666667" iyz="0.0" izz="0.0001"/>
    </inertial>
  </link>
  <!-- joint: screen -> plate -->
  <joint name="plate_top_to_screen_front" type="fixed">
    <origin rpy="0 0 0" xyz="0.3 0 0.02"/>
    <parent link="plate_top"/>
    <child link="screen_front"/>
  </joint>
  <!-- link: base -->
  <link name="screen_front">
    <visual>
      <origin rpy="0 0 0" xyz="0 0 0"/>
      <geometry>
        <box size="0.05 0.2 0.2"/>
      </geometry>
      <material name="Cyan"/>
    </visual>
    <collision>
      <origin rpy="0 0 0" xyz="0 0 0"/>
      <geometry>
        <box size="0.05 0.2 0.2"/>
      </geometry>
    </collision>
    <inertial>
      <mass value="0.1"/>
      <inertia ixx="0.0006666666666666668" ixy="0.0" ixz="0.0" iyy="0.00035416666666666675" iyz="0.0" izz="0.00035416666666666675"/>
    </inertial>
  </link>
  <!-- joint: screen -> plate -->
  <joint name="plate_top_to_screen_back" type="fixed">
    <origin rpy="0 0 0" xyz="-0.3 0 0.02"/>
    <parent link="plate_top"/>
    <child link="screen_back"/>
  </joint>
  <!-- link: base -->
  <link name="screen_back">
    <visual>
      <origin rpy="0 0 0" xyz="0 0 0"/>
      <geometry>
        <box size="0.05 0.2 0.2"/>
      </geometry>
      <material name="Cyan"/>
    </visual>
    <collision>
      <origin rpy="0 0 0" xyz="0 0 0"/>
      <geometry>
        <box size="0.05 0.2 0.2"/>
      </geometry>
    </collision>
    <inertial>
      <mass value="0.1"/>
      <inertia ixx="0.0006666666666666668" ixy="0.0" ixz="0.0" iyy="0.00035416666666666675" iyz="0.0" izz="0.00035416666666666675"/>
    </inertial>
  </link>
  <!-- joint: parent_base -> wheel -->
  <joint name="base_link_to_left_wheel" type="continuous">
    <origin rpy="0 0 0" xyz="-0.16 0.16 -0.0875"/>
    <parent link="base_scan"/>
    <child link="left_wheel"/>
    <axis xyz="0 1 0"/>
  </joint>
  <!-- link: wheel -->
  <link name="left_wheel">
    <origin rpy="-1.570796325 0 0" xyz="0 0 0"/>
    <visual>
      <origin rpy="0 0 0" xyz="0 0 0"/>
      <geometry>
        <sphere radius="0.075"/>
      </geometry>
    </visual>
    <collision>
      <origin rpy="0 0 0" xyz="0 0 0"/>
      <geometry>
        <sphere radius="0.075"/>
      </geometry>
    </collision>
    <inertial>
      <mass value="0.5"/>
      <inertia ixx="0.001125" ixy="0.0" ixz="0.0" iyy="0.001125" iyz="0.0" izz="0.001125"/>
    </inertial>
  </link>
  <!-- joint: parent_base -> wheel -->
  <joint name="base_link_to_right_wheel" type="continuous">
    <origin rpy="0 0 0" xyz="-0.16 -0.16 -0.0875"/>
    <parent link="base_scan"/>
    <child link="right_wheel"/>
    <axis xyz="0 1 0"/>
  </joint>
  <!-- link: wheel -->
  <link name="right_wheel">
    <origin rpy="-1.570796325 0 0" xyz="0 0 0"/>
    <visual>
      <origin rpy="0 0 0" xyz="0 0 0"/>
      <geometry>
        <sphere radius="0.075"/>
      </geometry>
    </visual>
    <collision>
      <origin rpy="0 0 0" xyz="0 0 0"/>
      <geometry>
        <sphere radius="0.075"/>
      </geometry>
    </collision>
    <inertial>
      <mass value="0.5"/>
      <inertia ixx="0.001125" ixy="0.0" ixz="0.0" iyy="0.001125" iyz="0.0" izz="0.001125"/>
    </inertial>
  </link>
  <!-- joint: parent_base -> wheel -->
  <joint name="base_link_to_front_wheel" type="continuous">
    <origin rpy="0 0 0" xyz="0.16 0.16 -0.0875"/>
    <parent link="base_scan"/>
    <child link="front_wheel"/>
    <axis xyz="0 1 0"/>
  </joint>
  <!-- link: wheel -->
  <link name="front_wheel">
    <origin rpy="-1.570796325 0 0" xyz="0 0 0"/>
    <visual>
      <origin rpy="0 0 0" xyz="0 0 0"/>
      <geometry>
        <sphere radius="0.075"/>
      </geometry>
    </visual>
    <collision>
      <origin rpy="0 0 0" xyz="0 0 0"/>
      <geometry>
        <sphere radius="0.075"/>
      </geometry>
    </collision>
    <inertial>
      <mass value="0.5"/>
      <inertia ixx="0.001125" ixy="0.0" ixz="0.0" iyy="0.001125" iyz="0.0" izz="0.001125"/>
    </inertial>
  </link>
  <!-- joint: parent_base -> wheel -->
  <joint name="base_link_to_front_wheel2" type="continuous">
    <origin rpy="0 0 0" xyz="0.16 -0.16 -0.0875"/>
    <parent link="base_scan"/>
    <child link="front_wheel2"/>
    <axis xyz="0 1 0"/>
  </joint>
  <!-- link: wheel -->
  <link name="front_wheel2">
    <origin rpy="-1.570796325 0 0" xyz="0 0 0"/>
    <visual>
      <origin rpy="0 0 0" xyz="0 0 0"/>
      <geometry>
        <sphere radius="0.075"/>
      </geometry>
    </visual>
    <collision>
      <origin rpy="0 0 0" xyz="0 0 0"/>
      <geometry>
        <sphere radius="0.075"/>
      </geometry>
    </collision>
    <inertial>
      <mass value="0.5"/>
      <inertia ixx="0.001125" ixy="0.0" ixz="0.0" iyy="0.001125" iyz="0.0" izz="0.001125"/>
    </inertial>
  </link>
  <!-- IMU
  <xacro:imu name="imu" parent="base_link">
    <origin xyz="0.0 0.0 0.055" rpy="0 0 0"/>
  </xacro:imu> -->
  <gazebo>
    <plugin filename="libgazebo_ros_diff_drive.so" name="diff_drive">
      <ros>
        <!-- <namespace>/r2d2</namespace> -->
        <!-- <remapping>cmd_vel:=cmd_vel</remapping> -->
        <!-- <remapping>odom:=odom</remapping> -->
      </ros>
      <update_rate>30</update_rate>
      <command_topic>cmd_vel</command_topic>
      <!-- wheels -->
      <left_joint>base_link_to_left_wheel</left_joint>
      <right_joint>base_link_to_right_wheel</right_joint>
      <!-- kinematics -->
      <wheel_separation>0.32</wheel_separation>
      <wheel_diameter>0.15</wheel_diameter>
      <!-- limits -->
      <max_wheel_torque>20</max_wheel_torque>
      <max_wheel_acceleration>1.0</max_wheel_acceleration>
      <!-- output -->
      <publish_odom>true</publish_odom>
      <publish_odom_tf>true</publish_odom_tf>
      <publish_wheel_tf>false</publish_wheel_tf>
      <odometry_topic>odom</odometry_topic>
      <odometry_frame>odom</odometry_frame>
      <robot_base_frame>base_footprint</robot_base_frame>
    </plugin>
  </gazebo>
  <!-- <plugin name="joint_state" filename="libgazebo_ros_joint_state_publisher.so">
      <ros>
        <remapping>~/out:=joint_states</remapping>
      </ros>
      <update_rate>30</update_rate>
      <joint_name>left_leg_base_to_left_center_wheel</joint_name>
      <joint_name>right_leg_base_to_right_center_wheel</joint_name>
      <joint_name>joint_base_footprint_to_base</joint_name>
    </plugin>   -->
  <gazebo reference="base_scan">
    <sensor name="base_scan" type="ray">
      <ray>
        <scan>
          <horizontal>
            <samples>180</samples>
            <resolution>1.0</resolution>
            <min_angle>-1.57</min_angle>
            <max_angle>1.57</max_angle>
          </horizontal>
        </scan>
        <range>
          <min>0.5</min>
          <max>30.0</max>
          <resolution>0.015000</resolution>
        </range>
      </ray>
      <always_on>true</always_on>
      <update_rate>100.0</update_rate>
      <visualize>true</visualize>
      <plugin filename="libgazebo_ros_ray_sensor.so" name="laserscan">
        <ros>
          <remapping>~/out:=scan</remapping>
        </ros>
        <output_type>sensor_msgs/LaserScan</output_type>
        <!-- <frame_name>base_scan</frame_name> -->
      </plugin>
    </sensor>
  </gazebo>
  <gazebo reference="camera_frente">
    <!-- <sensor name="sensor_${reference}" type="camera">

        <camera>
          <horizontal_fov>1.3962634</horizontal_fov>
          <image>
            <width>800</width>
            <height>800</height>
            <format>R8G8B8</format>
          </image>
          <clip>
            <near>0.04</near>
            <far>300</far>
          </clip>
        </camera>

        <plugin name="${reference}_controller" filename="libgazebo_ros_camera.so">
          <alwaysOn>true</alwaysOn>
          <updateRate>0.0</updateRate>
          <cameraName>camera_${reference}</cameraName>
          <imageTopicName>image_raw</imageTopicName>
          <cameraInfoTopicName>camera_info</cameraInfoTopicName>
          <frameName>${reference}</frameName>
          <hackBaseline>0.07</hackBaseline>
          <distortionK1>0.0</distortionK1>
          <distortionK2>0.0</distortionK2>
          <distortionK3>0.0</distortionK3>
          <distortionT1>0.0</distortionT1>
          <distortionT2>0.0</distortionT2>
        </plugin>

      </sensor> -->
    <sensor name="camera1" type="camera">
      <update_rate>60</update_rate>
      <visualize>true</visualize>
      <camera name="camera_frente">
        <horizontal_fov>1.3962634</horizontal_fov>
        <image>
          <width>640</width>
          <height>480</height>
          <format>R8G8B8</format>
        </image>
        <clip>
          <near>0.02</near>
          <far>300</far>
        </clip>
        <noise>
          <type>gaussian</type>
          <mean>0.0</mean>
          <stddev>0.007</stddev>
        </noise>
      </camera>
      <plugin filename="libgazebo_ros_camera.so" name="camera_controller">
        <ros>
          <namespace>r2d2</namespace>
          <!-- TODO(louise) Remapping not working due to https://github.com/ros-perception/image_common/issues/93 -->
          <!-- <remapping>image_raw:=image_demo</remapping> -->
          <!-- <remapping>camera_info:=camera_info_demo</remapping> -->
        </ros>
        <!-- camera_name>omit so it defaults to sensor name</camera_name-->
        <!-- frame_name>omit so it defaults to link name</frame_name-->
      </plugin>
    </sensor>
  </gazebo>
</robot>
